<?xml version="1.0" ?>
<!-- =================================================================================== -->
<!-- |    This document was autogenerated by xacro from ur10_robot_lacquey.urdf.xacro  | -->
<!-- |    EDITING THIS FILE BY HAND IS NOT RECOMMENDED                                 | -->
<!-- =================================================================================== -->
<robot name="ur10" xmlns:controller="http://playerstage.sourceforge.net/gazebo/xmlschema/#controller" xmlns:interface="http://playerstage.sourceforge.net/gazebo/xmlschema/#interface" xmlns:sensor="http://playerstage.sourceforge.net/gazebo/xmlschema/#sensor" xmlns:xacro="http://ros.org/wiki/xacro">
  <gazebo>
    <plugin filename="libgazebo_ros_control.so" name="ros_control">
      <!--robotNamespace>/</robotNamespace-->
      <!--robotSimType>gazebo_ros_control/DefaultRobotHWSim</robotSimType-->
    </plugin>
    <!--
    <plugin name="gazebo_ros_power_monitor_controller" filename="libgazebo_ros_power_monitor.so">
      <alwaysOn>true</alwaysOn>
      <updateRate>1.0</updateRate>
      <timeout>5</timeout>
      <powerStateTopic>power_state</powerStateTopic>
      <powerStateRate>10.0</powerStateRate>
      <fullChargeCapacity>87.78</fullChargeCapacity>     
      <dischargeRate>-474</dischargeRate>
      <chargeRate>525</chargeRate>
      <dischargeVoltage>15.52</dischargeVoltage>
      <chargeVoltage>16.41</chargeVoltage>
    </plugin>
-->
  </gazebo>
  <!--
  Author: Kelsey Hawkins 
  Contributers: Jimmy Da Silva, Ajit Krisshna N L, Muhammad Asif Rana 
-->
  <!--xacro:property name="pi" value="3.14159265" /-->
  <!-- measured from model -->
  <link name="ur10_base_link">
    <visual>
      <geometry>
        <mesh filename="package://tum_ics_ur10_description/meshes/ur10/visual/Base.dae"/>
      </geometry>
      <material name="LightGrey">
        <color rgba="0.7 0.7 0.7 1.0"/>
      </material>
    </visual>
    <collision>
      <geometry>
        <mesh filename="package://tum_ics_ur10_description/meshes/ur10/collision/base.stl"/>
      </geometry>
    </collision>
    <inertial>
      <mass value="4.0"/>
      <origin rpy="0 0 0" xyz="0.0 0.0 0.0"/>
      <inertia ixx="0.0061063308908" ixy="0.0" ixz="0.0" iyy="0.0061063308908" iyz="0.0" izz="0.01125"/>
    </inertial>
  </link>
  <joint name="ur10_shoulder_pan_joint" type="revolute">
    <parent link="ur10_base_link"/>
    <child link="ur10_shoulder_link"/>
    <origin rpy="0.0 0.0 0.0" xyz="0.0 0.0 0.1273"/>
    <axis xyz="0 0 1"/>
    <limit effort="330.0" lower="-6.28318530718" upper="6.28318530718" velocity="2.16"/>
    <dynamics damping="0.0" friction="0.0"/>
  </joint>
  <link name="ur10_shoulder_link">
    <visual>
      <geometry>
        <mesh filename="package://tum_ics_ur10_description/meshes/ur10/visual/Shoulder.dae"/>
      </geometry>
      <material name="LightGrey">
        <color rgba="0.7 0.7 0.7 1.0"/>
      </material>
    </visual>
    <collision>
      <geometry>
        <mesh filename="package://tum_ics_ur10_description/meshes/ur10/collision/shoulder.stl"/>
      </geometry>
    </collision>
    <inertial>
      <mass value="7.778"/>
      <origin rpy="0 0 0" xyz="0.0 0.0 0.0"/>
      <inertia ixx="0.0314743125769" ixy="0.0" ixz="0.0" iyy="0.0314743125769" iyz="0.0" izz="0.021875625"/>
    </inertial>
  </link>
  <joint name="ur10_shoulder_lift_joint" type="revolute">
    <parent link="ur10_shoulder_link"/>
    <child link="ur10_upper_arm_link"/>
    <origin rpy="0.0 1.57079632679 0.0" xyz="0.0 0.220941 0.0"/>
    <axis xyz="0 1 0"/>
    <limit effort="330.0" lower="-6.28318530718" upper="6.28318530718" velocity="2.16"/>
    <dynamics damping="0.0" friction="0.0"/>
  </joint>
  <link name="ur10_upper_arm_link">
    <visual>
      <geometry>
        <mesh filename="package://tum_ics_ur10_description/meshes/ur10/visual/UpperArm.dae"/>
      </geometry>
      <material name="LightGrey">
        <color rgba="0.7 0.7 0.7 1.0"/>
      </material>
    </visual>
    <collision>
      <geometry>
        <mesh filename="package://tum_ics_ur10_description/meshes/ur10/collision/upper_arm.stl"/>
      </geometry>
    </collision>
    <inertial>
      <mass value="12.93"/>
      <origin rpy="0 0 0" xyz="0.0 0.0 0.306"/>
      <inertia ixx="0.421753803798" ixy="0.0" ixz="0.0" iyy="0.421753803798" iyz="0.0" izz="0.036365625"/>
    </inertial>
  </link>
  <joint name="ur10_elbow_joint" type="revolute">
    <parent link="ur10_upper_arm_link"/>
    <child link="ur10_forearm_link"/>
    <origin rpy="0.0 0.0 0.0" xyz="0.0 -0.1719 0.612"/>
    <axis xyz="0 1 0"/>
    <limit effort="150.0" lower="-6.28318530718" upper="6.28318530718" velocity="3.15"/>
    <dynamics damping="0.0" friction="0.0"/>
  </joint>
  <link name="ur10_forearm_link">
    <visual>
      <geometry>
        <mesh filename="package://tum_ics_ur10_description/meshes/ur10/visual/Forearm.dae"/>
      </geometry>
      <material name="LightGrey">
        <color rgba="0.7 0.7 0.7 1.0"/>
      </material>
    </visual>
    <collision>
      <geometry>
        <mesh filename="package://tum_ics_ur10_description/meshes/ur10/collision/forearm.stl"/>
      </geometry>
    </collision>
    <inertial>
      <mass value="3.87"/>
      <origin rpy="0 0 0" xyz="0.0 0.0 0.28615"/>
      <inertia ixx="0.111069694097" ixy="0.0" ixz="0.0" iyy="0.111069694097" iyz="0.0" izz="0.010884375"/>
    </inertial>
  </link>
  <joint name="ur10_wrist_1_joint" type="revolute">
    <parent link="ur10_forearm_link"/>
    <child link="ur10_wrist_1_link"/>
    <origin rpy="0.0 1.57079632679 0.0" xyz="0.0 0.0 0.5723"/>
    <axis xyz="0 1 0"/>
    <limit effort="54.0" lower="-6.28318530718" upper="6.28318530718" velocity="3.2"/>
    <dynamics damping="0.0" friction="0.0"/>
  </joint>
  <link name="ur10_wrist_1_link">
    <visual>
      <geometry>
        <mesh filename="package://tum_ics_ur10_description/meshes/ur10/visual/Wrist1.dae"/>
      </geometry>
      <material name="LightGrey">
        <color rgba="0.7 0.7 0.7 1.0"/>
      </material>
    </visual>
    <collision>
      <geometry>
        <mesh filename="package://tum_ics_ur10_description/meshes/ur10/collision/wrist_1.stl"/>
      </geometry>
    </collision>
    <inertial>
      <mass value="1.96"/>
      <origin rpy="0 0 0" xyz="0.0 0.0 0.0"/>
      <inertia ixx="0.0051082479567" ixy="0.0" ixz="0.0" iyy="0.0051082479567" iyz="0.0" izz="0.0055125"/>
    </inertial>
  </link>
  <joint name="ur10_wrist_2_joint" type="revolute">
    <parent link="ur10_wrist_1_link"/>
    <child link="ur10_wrist_2_link"/>
    <origin rpy="0.0 0.0 0.0" xyz="0.0 0.1149 0.0"/>
    <axis xyz="0 0 1"/>
    <limit effort="54.0" lower="-6.28318530718" upper="6.28318530718" velocity="3.2"/>
    <dynamics damping="0.0" friction="0.0"/>
  </joint>
  <link name="ur10_wrist_2_link">
    <visual>
      <geometry>
        <mesh filename="package://tum_ics_ur10_description/meshes/ur10/visual/Wrist2.dae"/>
      </geometry>
      <material name="LightGrey">
        <color rgba="0.7 0.7 0.7 1.0"/>
      </material>
    </visual>
    <collision>
      <geometry>
        <mesh filename="package://tum_ics_ur10_description/meshes/ur10/collision/wrist_2.stl"/>
      </geometry>
    </collision>
    <inertial>
      <mass value="1.96"/>
      <origin rpy="0 0 0" xyz="0.0 0.0 0.0"/>
      <inertia ixx="0.0051082479567" ixy="0.0" ixz="0.0" iyy="0.0051082479567" iyz="0.0" izz="0.0055125"/>
    </inertial>
  </link>
  <joint name="ur10_wrist_3_joint" type="revolute">
    <parent link="ur10_wrist_2_link"/>
    <child link="ur10_wrist_3_link"/>
    <origin rpy="0.0 0.0 0.0" xyz="0.0 0.0 0.1157"/>
    <axis xyz="0 1 0"/>
    <limit effort="54.0" lower="-6.28318530718" upper="6.28318530718" velocity="3.2"/>
    <dynamics damping="0.0" friction="0.0"/>
  </joint>
  <link name="ur10_wrist_3_link">
    <visual>
      <geometry>
        <mesh filename="package://tum_ics_ur10_description/meshes/ur10/visual/Wrist3.dae"/>
      </geometry>
      <material name="LightGrey">
        <color rgba="0.7 0.7 0.7 1.0"/>
      </material>
    </visual>
    <collision>
      <geometry>
        <mesh filename="package://tum_ics_ur10_description/meshes/ur10/collision/wrist_3.stl"/>
      </geometry>
    </collision>
    <inertial>
      <mass value="0.202"/>
      <origin rpy="0 0 0" xyz="0.0 0.0 0.0"/>
      <inertia ixx="0.000526462289415" ixy="0.0" ixz="0.0" iyy="0.000526462289415" iyz="0.0" izz="0.000568125"/>
    </inertial>
  </link>
  <joint name="ur10_ee_fixed_joint" type="fixed">
    <parent link="ur10_wrist_3_link"/>
    <child link="ur10_ee_link"/>
    <origin rpy="0.0 0.0 1.57079632679" xyz="0.0 0.0922 0.0"/>
  </joint>
  <link name="ur10_ee_link">
    <collision>
      <geometry>
        <box size="0.01 0.01 0.01"/>
      </geometry>
      <origin rpy="0 0 0" xyz="-0.01 0 0"/>
    </collision>
  </link>
  <transmission name="ur10_shoulder_pan_trans">
    <type>transmission_interface/SimpleTransmission</type>
    <joint name="ur10_shoulder_pan_joint">
      <hardwareInterface>EffortJointInterface</hardwareInterface>
    </joint>
    <actuator name="ur10_shoulder_pan_motor">
      <mechanicalReduction>1</mechanicalReduction>
    </actuator>
  </transmission>
  <transmission name="ur10_shoulder_lift_trans">
    <type>transmission_interface/SimpleTransmission</type>
    <joint name="ur10_shoulder_lift_joint">
      <hardwareInterface>EffortJointInterface</hardwareInterface>
    </joint>
    <actuator name="ur10_shoulder_lift_motor">
      <mechanicalReduction>1</mechanicalReduction>
    </actuator>
  </transmission>
  <transmission name="ur10_elbow_trans">
    <type>transmission_interface/SimpleTransmission</type>
    <joint name="ur10_elbow_joint">
      <hardwareInterface>EffortJointInterface</hardwareInterface>
    </joint>
    <actuator name="ur10_elbow_motor">
      <mechanicalReduction>1</mechanicalReduction>
    </actuator>
  </transmission>
  <transmission name="ur10_wrist_1_trans">
    <type>transmission_interface/SimpleTransmission</type>
    <joint name="ur10_wrist_1_joint">
      <hardwareInterface>EffortJointInterface</hardwareInterface>
    </joint>
    <actuator name="ur10_wrist_1_motor">
      <mechanicalReduction>1</mechanicalReduction>
    </actuator>
  </transmission>
  <transmission name="ur10_wrist_2_trans">
    <type>transmission_interface/SimpleTransmission</type>
    <joint name="ur10_wrist_2_joint">
      <hardwareInterface>EffortJointInterface</hardwareInterface>
    </joint>
    <actuator name="ur10_wrist_2_motor">
      <mechanicalReduction>1</mechanicalReduction>
    </actuator>
  </transmission>
  <transmission name="ur10_wrist_3_trans">
    <type>transmission_interface/SimpleTransmission</type>
    <joint name="ur10_wrist_3_joint">
      <hardwareInterface>EffortJointInterface</hardwareInterface>
    </joint>
    <actuator name="ur10_wrist_3_motor">
      <mechanicalReduction>1</mechanicalReduction>
    </actuator>
  </transmission>
  <!-- nothing to do here at the moment -->
  <link name="world"/>
  <joint name="world_joint" type="fixed">
    <parent link="world"/>
    <child link="ur10_base_link"/>
    <origin rpy="0.0 0.0 0.0" xyz="0.0 0.0 0.0"/>
  </joint>
  <!-- This is the JR3 adapter -->
  <link name="ur10_hand_base_adapter_link">
    <visual>
      <origin rpy="1.57079632679 0 1.57079632679" xyz="0 0 -0.045"/>
      <geometry>
        <mesh filename="package://tum_ics_ur10_description/meshes/arm/mountc.dae"/>
      </geometry>
    </visual>
    <collision>
      <origin rpy="0 0 0" xyz="0 0 -0.025"/>
      <geometry>
        <cylinder length="0.05" radius="0.035"/>
      </geometry>
    </collision>
  </link>
  <joint name="ur10_hand_base_adapter_joint" type="fixed">
    <parent link="ur10_ee_link"/>
    <child link="ur10_hand_base_adapter_link"/>
    <origin rpy="1.57079632679 2.356 1.57079632679" xyz="0.045 0 0"/>
  </joint>
  <!--xacro:property name="limit_0_low" value="-${M_PI/4}" />
    <xacro:property name="limit_1_up" value="${M_PI/180*67}" /-->
  <!-- the bumper ring -->
  <link name="ur10_gripper_base_link">
    <visual>
      <origin rpy="0 0 0" xyz="-0.065 -0.065 0.003"/>
      <geometry>
        <mesh filename="package://tum_ics_ur10_description/meshes/lacquey/Lacquey_BumperRing_2.STL" scale="0.001 0.001 0.001"/>
      </geometry>
    </visual>
    <collision>
      <origin rpy="0 0 0" xyz="0 0 0.04"/>
      <geometry>
        <cylinder length="0.08" radius="0.07"/>
      </geometry>
    </collision>
    <inertial>
      <origin rpy="0 0 0" xyz="0 0 0.04"/>
      <mass value="0.5"/>
      <inertia ixx="0.00001" ixy="0" ixz="0" iyy="0.00001" iyz="0" izz="0.00001"/>
    </inertial>
  </link>
  <link name="ur10_gripper_palm_link">
    <visual>
      <origin rpy="1.57079632679 0 1.57079632679" xyz="-0.046 -0.040 0"/>
      <geometry>
        <mesh filename="package://tum_ics_ur10_description/meshes/lacquey/Lacquey_Palm.STL" scale="0.001 0.001 0.001"/>
      </geometry>
      <material name="LightGrey">
        <color rgba="0.7 0.7 0.7 1.0"/>
      </material>
    </visual>
    <collision>
      <origin rpy="0 0 0" xyz="0 0 0.04"/>
      <geometry>
        <box size="0.1 0.1 0.08"/>
      </geometry>
    </collision>
    <inertial>
      <origin rpy="0 0 0" xyz="0 0 0.04"/>
      <mass value="0.15"/>
      <inertia ixx="0.00001" ixy="0" ixz="0" iyy="0.00001" iyz="0" izz="0.00001"/>
    </inertial>
  </link>
  <joint name="ur10_gripper_palm_joint" type="fixed">
    <parent link="ur10_gripper_base_link"/>
    <child link="ur10_gripper_palm_link"/>
    <origin rpy="0 0 0" xyz="0 0 0"/>
  </joint>
  <!-- left finger -->
  <link name="ur10_gripper_left_finger_link">
    <visual>
      <origin rpy="1.57079632679 0 3.14159265359" xyz="0.0115 -0.005 -0.010"/>
      <geometry>
        <mesh filename="package://tum_ics_ur10_description/meshes/lacquey/Lacquey_Left_Finger.STL" scale="0.001 0.001 0.001"/>
      </geometry>
    </visual>
    <collision>
      <origin rpy="0 0 0" xyz="0 0.01 0.03"/>
      <geometry>
        <box size="0.01 0.03 0.037"/>
      </geometry>
    </collision>
    <inertial>
      <origin rpy="0 0 0" xyz="0 0 0.04"/>
      <mass value="0.05"/>
      <inertia ixx="0.000001" ixy="0" ixz="0" iyy="0.000001" iyz="0" izz="0.000001"/>
    </inertial>
  </link>
  <joint name="ur10_gripper_left_finger_joint" type="revolute">
    <axis xyz="0 -1 0"/>
    <limit effort="0" lower="0" upper="1.16937059884" velocity="0"/>
    <parent link="ur10_gripper_left_finger_base_link"/>
    <child link="ur10_gripper_left_finger_link"/>
    <origin rpy="0 0 0" xyz="0 0 0.054"/>
  </joint>
  <link name="ur10_gripper_left_finger_base_link">
    <visual>
      <origin rpy="1.57079632679 0 3.14159265359" xyz="0.018 -0.0075 -0.005"/>
      <geometry>
        <mesh filename="package://tum_ics_ur10_description/meshes/lacquey/Lacquey_proxph.STL" scale="0.001 0.001 0.001"/>
      </geometry>
      <material name="LightGrey">
        <color rgba="0.7 0.7 0.7 1.0"/>
      </material>
    </visual>
    <collision>
      <origin rpy="0 0 0" xyz="0 0 0.03"/>
      <geometry>
        <box size="0.01 0.02 0.045"/>
      </geometry>
    </collision>
    <inertial>
      <origin rpy="0 0 0" xyz="0 0 0.04"/>
      <mass value="0.05"/>
      <inertia ixx="0.000001" ixy="0" ixz="0" iyy="0.000001" iyz="0" izz="0.000001"/>
    </inertial>
  </link>
  <joint name="ur10_gripper_left_finger_base_joint" type="revolute">
    <axis xyz="0 -1 0"/>
    <limit effort="0" lower="-0.785398163397" upper="0" velocity="0"/>
    <parent link="ur10_gripper_base_link"/>
    <child link="ur10_gripper_left_finger_base_link"/>
    <origin rpy="0 0 -1.57079632679" xyz="0.020 -0.028 0.072"/>
  </joint>
  <!-- right finger -->
  <link name="ur10_gripper_right_finger_link">
    <visual>
      <origin rpy="1.57079632679 0 3.14159265359" xyz="0.0115 -0.02571 -0.010"/>
      <geometry>
        <mesh filename="package://tum_ics_ur10_description/meshes/lacquey/Lacquey_Right_Finger.STL" scale="0.001 0.001 0.001"/>
      </geometry>
    </visual>
    <collision>
      <origin rpy="0 0 0" xyz="0 -0.01 0.03"/>
      <geometry>
        <box size="0.01 0.03 0.037"/>
      </geometry>
    </collision>
    <inertial>
      <origin rpy="0 0 0" xyz="0 0 0.04"/>
      <mass value="0.05"/>
      <inertia ixx="0.000001" ixy="0" ixz="0" iyy="0.000001" iyz="0" izz="0.000001"/>
    </inertial>
  </link>
  <joint name="ur10_gripper_right_finger_joint" type="revolute">
    <axis xyz="0 -1 0"/>
    <limit effort="0" lower="0" upper="1.16937059884" velocity="0"/>
    <parent link="ur10_gripper_right_finger_base_link"/>
    <child link="ur10_gripper_right_finger_link"/>
    <origin rpy="0 0 0" xyz="0 0 0.054"/>
  </joint>
  <link name="ur10_gripper_right_finger_base_link">
    <visual>
      <origin rpy="1.57079632679 0 3.14159265359" xyz="0.018 -0.0075 -0.005"/>
      <geometry>
        <mesh filename="package://tum_ics_ur10_description/meshes/lacquey/Lacquey_proxph.STL" scale="0.001 0.001 0.001"/>
      </geometry>
      <material name="LightGrey">
        <color rgba="0.7 0.7 0.7 1.0"/>
      </material>
    </visual>
    <collision>
      <origin rpy="0 0 0" xyz="0 0 0.03"/>
      <geometry>
        <box size="0.01 0.02 0.045"/>
      </geometry>
    </collision>
    <inertial>
      <origin rpy="0 0 0" xyz="0 0 0.04"/>
      <mass value="0.05"/>
      <inertia ixx="0.000001" ixy="0" ixz="0" iyy="0.000001" iyz="0" izz="0.000001"/>
    </inertial>
  </link>
  <joint name="ur10_gripper_right_finger_base_joint" type="revolute">
    <axis xyz="0 -1 0"/>
    <limit effort="0" lower="-0.785398163397" upper="0" velocity="0"/>
    <parent link="ur10_gripper_base_link"/>
    <child link="ur10_gripper_right_finger_base_link"/>
    <origin rpy="0 0 -1.57079632679" xyz="-0.023 -0.028 0.072"/>
  </joint>
  <!-- mid finger -->
  <link name="ur10_gripper_mid_finger_link">
    <visual>
      <origin rpy="1.57079632679 0 3.14159265359" xyz="0.0115 -0.01386 -0.010"/>
      <geometry>
        <mesh filename="package://tum_ics_ur10_description/meshes/lacquey/Lacquey_Mid_Finger.STL" scale="0.001 0.001 0.001"/>
      </geometry>
    </visual>
    <collision>
      <origin rpy="0 0 0" xyz="0 0 0.03"/>
      <geometry>
        <box size="0.01 0.03 0.037"/>
      </geometry>
    </collision>
    <inertial>
      <origin rpy="0 0 0" xyz="0 0 0.04"/>
      <mass value="0.05"/>
      <inertia ixx="0.000001" ixy="0" ixz="0" iyy="0.000001" iyz="0" izz="0.000001"/>
    </inertial>
  </link>
  <joint name="ur10_gripper_mid_finger_joint" type="revolute">
    <axis xyz="0 -1 0"/>
    <limit effort="0" lower="0" upper="1.16937059884" velocity="0"/>
    <parent link="ur10_gripper_mid_finger_base_link"/>
    <child link="ur10_gripper_mid_finger_link"/>
    <origin rpy="0 0 0" xyz="0 0 0.054"/>
  </joint>
  <link name="ur10_gripper_mid_finger_base_link">
    <visual>
      <origin rpy="1.57079632679 0 3.14159265359" xyz="0.018 -0.0075 -0.005"/>
      <geometry>
        <mesh filename="package://tum_ics_ur10_description/meshes/lacquey/Lacquey_proxph.STL" scale="0.001 0.001 0.001"/>
      </geometry>
      <material name="LightGrey">
        <color rgba="0.7 0.7 0.7 1.0"/>
      </material>
    </visual>
    <collision>
      <origin rpy="0 0 0" xyz="0 0 0.03"/>
      <geometry>
        <box size="0.01 0.02 0.045"/>
      </geometry>
    </collision>
    <inertial>
      <origin rpy="0 0 0" xyz="0 0 0.04"/>
      <mass value="0.05"/>
      <inertia ixx="0.000001" ixy="0" ixz="0" iyy="0.000001" iyz="0" izz="0.000001"/>
    </inertial>
  </link>
  <joint name="ur10_gripper_mid_finger_base_joint" type="revolute">
    <axis xyz="0 -1 0"/>
    <limit effort="0" lower="-0.785398163397" upper="0" velocity="0"/>
    <parent link="ur10_gripper_base_link"/>
    <child link="ur10_gripper_mid_finger_base_link"/>
    <origin rpy="0 0 1.57079632679" xyz="0 0.028 0.072"/>
  </joint>
  <joint name="ur10_gripper_base_joint" type="fixed">
    <parent link="ur10_hand_base_adapter_link"/>
    <child link="ur10_gripper_base_link"/>
    <origin rpy="0 0 -0.785398163397" xyz="0 0 -0.04"/>
  </joint>
</robot>

